Workbook

Sheet Podsumowanie
A1: Kraj | B1: Liczba kontaktów | C1: Z mailem osoby | D1: Priorytet 1 | E1: Zweryfikowane
A2: Szwecja | B2: =COUNTIF(Kontakty!$A$2:$A$124,A2) | C2: =COUNTIFS(Kontakty!$A$2:$A$124,A2,Kontakty!$F$2:$F$124,"*@*") | D2: =COUNTIFS(Kontakty!$A$2:$A$124,A2,Kontakty!$I$2:$I$124,1) | E2: =COUNTIFS(Kontakty!$A$2:$A$124,A2,Kontakty!$J$2:$J$124,"Zweryfikowany")
A3: Dania | B3: =COUNTIF(Kontakty!$A$2:$A$124,A3) | C3: =COUNTIFS(Kontakty!$A$2:$A$124,A3,Kontakty!$F$2:$F$124,"*@*") | D3: =COUNTIFS(Kontakty!$A$2:$A$124,A3,Kontakty!$I$2:$I$124,1) | E3: =COUNTIFS(Kontakty!$A$2:$A$124,A3,Kontakty!$J$2:$J$124,"Zweryfikowany")
A4: Włochy | B4: =COUNTIF(Kontakty!$A$2:$A$124,A4) | C4: =COUNTIFS(Kontakty!$A$2:$A$124,A4,Kontakty!$F$2:$F$124,"*@*") | D4: =COUNTIFS(Kontakty!$A$2:$A$124,A4,Kontakty!$I$2:$I$124,1) | E4: =COUNTIFS(Kontakty!$A$2:$A$124,A4,Kontakty!$J$2:$J$124,"Zweryfikowany")
A5: Francja | B5: =COUNTIF(Kontakty!$A$2:$A$124,A5) | C5: =COUNTIFS(Kontakty!$A$2:$A$124,A5,Kontakty!$F$2:$F$124,"*@*") | D5: =COUNTIFS(Kontakty!$A$2:$A$124,A5,Kontakty!$I$2:$I$124,1) | E5: =COUNTIFS(Kontakty!$A$2:$A$124,A5,Kontakty!$J$2:$J$124,"Zweryfikowany")
A6: Belgia | B6: =COUNTIF(Kontakty!$A$2:$A$124,A6) | C6: =COUNTIFS(Kontakty!$A$2:$A$124,A6,Kontakty!$F$2:$F$124,"*@*") | D6: =COUNTIFS(Kontakty!$A$2:$A$124,A6,Kontakty!$I$2:$I$124,1) | E6: =COUNTIFS(Kontakty!$A$2:$A$124,A6,Kontakty!$J$2:$J$124,"Zweryfikowany")
A7: Austria | B7: =COUNTIF(Kontakty!$A$2:$A$124,A7) | C7: =COUNTIFS(Kontakty!$A$2:$A$124,A7,Kontakty!$F$2:$F$124,"*@*") | D7: =COUNTIFS(Kontakty!$A$2:$A$124,A7,Kontakty!$I$2:$I$124,1) | E7: =COUNTIFS(Kontakty!$A$2:$A$124,A7,Kontakty!$J$2:$J$124,"Zweryfikowany")
A8: Szwajcaria | B8: =COUNTIF(Kontakty!$A$2:$A$124,A8) | C8: =COUNTIFS(Kontakty!$A$2:$A$124,A8,Kontakty!$F$2:$F$124,"*@*") | D8: =COUNTIFS(Kontakty!$A$2:$A$124,A8,Kontakty!$I$2:$I$124,1) | E8: =COUNTIFS(Kontakty!$A$2:$A$124,A8,Kontakty!$J$2:$J$124,"Zweryfikowany")
A9: Portugalia | B9: =COUNTIF(Kontakty!$A$2:$A$124,A9) | C9: =COUNTIFS(Kontakty!$A$2:$A$124,A9,Kontakty!$F$2:$F$124,"*@*") | D9: =COUNTIFS(Kontakty!$A$2:$A$124,A9,Kontakty!$I$2:$I$124,1) | E9: =COUNTIFS(Kontakty!$A$2:$A$124,A9,Kontakty!$J$2:$J$124,"Zweryfikowany")
A10: Holandia | B10: =COUNTIF(Kontakty!$A$2:$A$124,A10) | C10: =COUNTIFS(Kontakty!$A$2:$A$124,A10,Kontakty!$F$2:$F$124,"*@*") | D10: =COUNTIFS(Kontakty!$A$2:$A$124,A10,Kontakty!$I$2:$I$124,1) | E10: =COUNTIFS(Kontakty!$A$2:$A$124,A10,Kontakty!$J$2:$J$124,"Zweryfikowany")
A11: Hiszpania | B11: =COUNTIF(Kontakty!$A$2:$A$124,A11) | C11: =COUNTIFS(Kontakty!$A$2:$A$124,A11,Kontakty!$F$2:$F$124,"*@*") | D11: =COUNTIFS(Kontakty!$A$2:$A$124,A11,Kontakty!$I$2:$I$124,1) | E11: =COUNTIFS(Kontakty!$A$2:$A$124,A11,Kontakty!$J$2:$J$124,"Zweryfikowany")
A12: Niemcy | B12: =COUNTIF(Kontakty!$A$2:$A$124,A12) | C12: =COUNTIFS(Kontakty!$A$2:$A$124,A12,Kontakty!$F$2:$F$124,"*@*") | D12: =COUNTIFS(Kontakty!$A$2:$A$124,A12,Kontakty!$I$2:$I$124,1) | E12: =COUNTIFS(Kontakty!$A$2:$A$124,A12,Kontakty!$J$2:$J$124,"Zweryfikowany")
A13: Chorwacja | B13: =COUNTIF(Kontakty!$A$2:$A$124,A13) | C13: =COUNTIFS(Kontakty!$A$2:$A$124,A13,Kontakty!$F$2:$F$124,"*@*") | D13: =COUNTIFS(Kontakty!$A$2:$A$124,A13,Kontakty!$I$2:$I$124,1) | E13: =COUNTIFS(Kontakty!$A$2:$A$124,A13,Kontakty!$J$2:$J$124,"Zweryfikowany")
... A16: Anglia | B16: =COUNTIF(Kontakty!$A$2:$A$124,A16) | C16: =COUNTIFS(Kontakty!$A$2:$A$124,A16,Kontakty!$F$2:$F$124,"*@*") | D16: =COUNTIFS(Kontakty!$A$2:$A$124,A16,Kontakty!$I$2:$I$124,1) | E16: =COUNTIFS(Kontakty!$A$2:$A$124,A16,Kontakty!$J$2:$J$124,"Zweryfikowany")
A17: RAZEM | B17: =SUM(B2:B16) | C17: =SUM(C2:C16) | D17: =SUM(D2:D16) | E17: =SUM(E2:E16)
A20: Legenda
A21: Zweryfikowany – e-mail/kontakt opublikowany na oficjalnej stronie klubu (wiersz na zielono).
A22: Częściowo – brak maila osoby – osoba i stanowisko potwierdzone, ale e-mail osoby nie jest publiczny lub jest ukryty przed botami; użyj kontaktu klubu.
A23: Do potwierdzenia – dane ze źródła starszego lub nieoficjalnego; potwierdzić przed wysyłką (wiersz na pomarańczowo).
A24: Priorytet: 1 = kontaktować w pierwszej kolejności, 3 = niski. Szwecja = kraj priorytetowy.
A25: Nie podajemy maili z komercyjnych baz (RocketReach, Lusha itp.) ani maili zgadywanych z formatu domeny.
A26: Belgia: wszystkie 18 klubów Pro League 26/27; Austria: 12 klubów Bundesligi; Szwajcaria: 12 klubów Super League.
A27: Dania: wszystkie 12 klubów Superligi i 12 klubów 1. Division (sezon 26/27, wg Transfermarkt). Oceny akademii: licencja DBU 2026–2028.
A28: Stan na: 26.09.2026. Stanowiska w klubach zmieniają się często – przed kampanią sprawdź źródło w kolumnie H.

Sheet Kontakty
A1: Kraj | B1: Klub | C1: Osoba | D1: Stanowisko | E1: Obszar działania | F1: E-mail osoby (zweryfikowany) | G1: Oficjalny kontakt klubu | H1: Źródło | I1: Priorytet (1–3) | J1: Status weryfikacji | K1: Uwagi
A2: Szwecja | B2: AIK | C2: Miika Takkula | D2: Head of Recruitment (Rekryteringschef) | E2: Rekrutacja seniorska, planowanie kadry, transfery | F2: miika.takkula@aikfotboll.se | G2: ungdom@aikfotboll.se | H2: https://www.aikfotboll.se/kontakta-oss/kontakt-med-lagen | I2: 1 | J2: Zweryfikowany | K2: Zatrudniony XII 2025
A3: Szwecja | B3: AIK | C3: Herish Sadi | D3: Chefsscout (Chief Scout) | E3: Live-scouting, talenty krajowe, rynek afrykański | F3: herish.sadi@aikfotboll.se | G3: ungdom@aikfotboll.se | H3: https://www.aikfotboll.se/kontakta-oss/kontakt-med-lagen | I3: 1 | J3: Zweryfikowany
A4: Szwecja | B4: AIK | C4: Alexander Milošević | D4: Scout & Rekryteringsansvarig, Akademi | E4: Scouting i rekrutacja do akademii | F4: alexander.milosevic@aikfotboll.se | G4: ungdom@aikfotboll.se | H4: https://www.aikfotboll.se/artiklar-och-nyheter/260130-alexander-milosevic-ny-scout-och-rekryteringsansvarig-for-akademin | I4: 1 | J4: Zweryfikowany | K4: Umowa 01.02.2026–31.12.2027
A5: Szwecja | B5: IFK Göteborg | C5: Jonas Olsson | D5: Akademichef (Academy Director) | E5: Akademia | F5: jonas.olsson@ifkgoteborg.se | H5: https://ifkgoteborg.se/om-ifk-goteborg/kontakt/ | I5: 1 | J5: Zweryfikowany
A6: Szwecja | B6: Hammarby IF | C6: Atilla Börjeson | D6: Scout- och rekryteringsansvarig, pojkar | E6: Scouting/rekrutacja akademii (chłopcy) | F6: atilla.borjeson@hammarbyungdom.se | G6: 08-462 88 10 | H6: https://www.hammarbyfotboll.se/kontakt/ | I6: 1 | J6: Zweryfikowany
A7: Szwecja | B7: Hammarby IF | C7: Mathias Rosengård | D7: Akademichef HTFF (Hammarby Talang FF) | E7: Akademia / drużyna rozwojowa | F7: mathias.rosengard@hammarbyungdom.se | G7: 08-462 88 10 | H7: https://www.hammarbyfotboll.se/kontakt/ | I7: 1 | J7: Zweryfikowany
A8: Szwecja | B8: Djurgårdens IF | C8: (funkcja) Rekrytering P15–19 | D8: Rekrytering P15–P19 | E8: Rekrutacja akademii U15–U19 | F8: ukryty na stronie (ochrona antyspamowa) – skopiuj ze strony | G8: Djurgårdens Elitfotboll AB, Box 24053, 104 50 Stockholm | H8: https://www.dif.se/om-dif/kontakt | I8: 1 | J8: Częściowo – brak maila osoby | K8: Na stronie także: Akademichef A10-15/PA16-19, Utvecklingschef PA16-19
A9: Szwecja | B9: BK Häcken | C9: Alfons Petersson | D9: Scoutingansvarig Akademi/Ungdom | E9: Scouting akademii | F9: ukryty na stronie (ochrona antyspamowa) – skopiuj ze strony | G9: tel. 073-544 94 11; scouttickets@bkhacken.se (akredytacje scoutów) | H9: https://bkhacken.se/sida/pojkakademi-ledare | I9: 1 | J9: Częściowo – brak maila osoby
A10: Szwecja | B10: Malmö FF | C10: — | D10: — | E10: Kontakt ogólny | G10: info@mff.se | H10: https://www.mff.se/om-malmo-ff/kontakt/ | I10: 2 | J10: Częściowo – brak maila osoby | K10: Brak publicznego maila do rekrutacji akademii
A11: Szwecja | B11: IF Elfsborg | C11: — | D11: — | E11: Kontakt ogólny | G11: info@elfsborg.se; 033-13 91 91 | H11: https://elfsborg.se/for-foretag/kontakta-oss/ | I11: 2 | J11: Częściowo – brak maila osoby | K11: Brak publicznego maila do rekrutacji akademii
A12: Dania | B12: FC Nordsjælland | C12: Herekol Tanrisever | D12: Head of Scouting & Recruitment U14–U19 | E12: Scouting/rekrutacja U14–U19 (chłopcy) | F12: ukryty na stronie (ochrona antyspamowa) – skopiuj ze strony | H12: https://fcn.dk/akademi/kontakt | I12: 1 | J12: Częściowo – brak maila osoby | K12: Superliga. Najlepsza akademia w DK 2026 (DBU 5★, 97,0/100)
A13: Dania | B13: FC Nordsjælland | C13: Bertram Pedersen | D13: Head of Scouting & Recruitment U11–U13 | E13: Scouting/rekrutacja U11–U13 (chłopcy) | F13: ukryty na stronie (ochrona antyspamowa) – skopiuj ze strony | H13: https://fcn.dk/akademi/kontakt | I13: 1 | J13: Częściowo – brak maila osoby | K13: Superliga
A14: Dania | B14: FC Midtjylland | C14: Kristian Kjær | D14: Director of Recruitment | E14: Rekrutacja (dział rekrutacji) | F14: kfk@fcm.dk | G14: uddannelse@fcm.dk | H14: https://www.fcm.dk/drengeakademiet/ | I14: 1 | J14: Zweryfikowany | K14: Superliga. DBU 5★. Head of Academy Recruitment: Mads Agner Veng (mail niepubliczny)
A15: Dania | B15: F.C. København | C15: Christian Wilkens | D15: Head of Recruitment (FCK Talent) | E15: Rekrutacja akademii (starsze roczniki) | H15: https://www.fck.dk/en/content/fck-talent-department-staff-and-officials | I15: 1 | J15: Częściowo – brak maila osoby | K15: Superliga. DBU 5★. Stanowisko U12–U13 wolne po odejściu R. Ankera do Lyngby (VIII 2026)
A16: Dania | B16: Brøndby IF | C16: Christian Morsing | D16: Rekrutteringsansvarlig, Brøndby Masterclass | E16: Kontakt z klubami ws. rekrutacji do akademii | G16: scouting.brondby.com; tel. +45 43 63 08 10 | H16: https://brondby.com/masterclass/om-masterclass/rekrutteringsprocedure-i-brondby-masterclass | I16: 1 | J16: Częściowo – brak maila osoby | K16: Superliga. DBU 4,5★ (89,39). Academy Director: Bjørn Holm; Head of Development: Jonas Bliksted
A17: Dania | B17: Lyngby Boldklub | C17: Karsten Stiig Alnor | D17: Akademichef | E17: Akademia | F17: ks@lyngby-boldklub.dk | H17: https://lyngby-boldklub.dk/kontakt/ | I17: 1 | J17: Zweryfikowany | K17: Superliga (beniaminek). DBU 4★
A18: Dania | B18: Lyngby Boldklub | C18: Rasmus Anker | D18: Chef for rekruttering og scouting | E18: Scouting/rekrutacja akademia → 1. zespół | H18: https://lyngby-boldklub.dk/2026/06/25/rasmus-anker-bliver-ny-chef-for-rekruttering-og-scouting/ | I18: 1 | J18: Częściowo – brak maila osoby | K18: Od 01.08.2026 (wcześniej FCK). Nowy mail niepubliczny – stary rsa@fck.dk nieaktualny
A19: Dania | B19: AGF | C19: Marc Søballe Pedersen | D19: Talentchef (AGF Talent) | E19: Akademia | H19: https://agf.dk/agf-talent | I19: 1 | J19: Częściowo – brak maila osoby | K19: Superliga. Rekrutacja U13–U17: Kenneth Djoeneri; U10–U12: René Klok
A20: Dania | B20: OB (Odense Boldklub) | C20: Ulrik Bredegaard | D20: Akademichef | E20: Akademia | F20: ulrik.bredegaard@ob.dk | H20: https://ob.dk/hold/akademi/akademiets-personale | I20: 1 | J20: Zweryfikowany | K20: Superliga. Talentchef: Benjamin Ajslev
A21: Dania | B21: Silkeborg IF | C21: Nicolaj Bækgaard | D21: Rekrutteringsansvarlig | E21: Zapytania ws. młodych zawodników | F21: nb@silkeborgif.com | G21: tel. 22 98 96 10 | H21: https://www.silkeborgif.com/talent/kontakt/ | I21: 1 | J21: Zweryfikowany | K21: Superliga
A22: Dania | B22: Silkeborg IF | C22: Peter Christian Hansen | D22: Talentchef | E22: Akademia | F22: pc@silkeborgif.com | G22: +45 20 27 58 35 | H22: https://www.silkeborgif.com/talent/kontakt/ | I22: 1 | J22: Zweryfikowany | K22: Superliga
A23: Dania | B23: Randers FC | C23: Peter Elstrup | D23: Talentchef & Head of Coaching | E23: Akademia | F23: pe@randersfc.dk | G23: +45 25 60 21 51; randersfc@randersfc.dk | H23: https://randersfc.dk/talent/kontakt/ | I23: 1 | J23: Zweryfikowany | K23: Superliga
A24: Dania | B24: AaB (Aalborg) | C24: Jakob Ahlmann | D24: Ansvarlig for kontraktspillere og rekruttering U15–U19 | E24: Rekrutacja do akademii | F24: jah@aab-as.dk | G24: tel. 28 40 15 89 | H24: https://aabsport.dk/akademiet/om-aab-akademiet/ | I24: 1 | J24: Zweryfikowany | K24: 1. Division. Rola od 01.02.2026
A25: Dania | B25: AaB (Aalborg) | C25: Mathias Krogh | D25: Akademichef | E25: Akademia | F25: mak@aab-as.dk | H25: https://aabsport.dk/akademiet/om-aab-akademiet/ | I25: 1 | J25: Zweryfikowany | K25: 1. Division
A26: Dania | B26: FC Nordsjælland | C26: David Poulsen | D26: Lead Scout U7–U10 | E26: Scouting U7–U10 | F26: ukryty na stronie (ochrona antyspamowa) – skopiuj ze strony | H26: https://fcn.dk/akademi/kontakt | I26: 2 | J26: Częściowo – brak maila osoby | K26: Superliga
A27: Dania | B27: F.C. København | C27: Rasmus Hahnemann | D27: Head Scout & Recruitment Manager U10–U11, ATK+ | E27: Scouting/rekrutacja U10–U11 | F27: raha@fck.dk | H27: https://www.fck.dk/indhold/procedurer-rekruttering-i-talentafdelingen | I27: 2 | J27: Zweryfikowany | K27: Superliga
A28: Dania | B28: Viborg FF | C28: Mads Holm | D28: Talentchef | E28: Akademia | F28: ukryty na stronie (ochrona antyspamowa) – skopiuj ze strony | G28: kundeservice@vff.dk | H28: https://www.vff.dk/viborg-f-f/kontaktinfo | I28: 2 | J28: Częściowo – brak maila osoby | K28: Superliga
A29: Dania | B29: Sønderjyske Fodbold | C29: Joshua Karesch | D29: Scout & Recruitment Manager | E29: Scouting/rekrutacja akademii | F29: jk@soenderjyskefodbold.dk | H29: https://soenderjyskefodbold.dk/scouting-rekruttering/ | I29: 2 | J29: Zweryfikowany | K29: Superliga. Scout: Steffen Dam – dam@soenderjyskefodbold.dk
A30: Dania | B30: AC Horsens | C30: Martin Bloch | D30: Talentchef | E30: Akademia | F30: ukryty na stronie (ochrona antyspamowa) – skopiuj ze strony | G30: tel. 75 62 60 20 | H30: https://achorsens.dk/ansatte/akademiet | I30: 2 | J30: Częściowo – brak maila osoby | K30: Superliga (beniaminek)
A31: Dania | B31: Vejle Boldklub | C31: Steen Thychosen | D31: Talentchef | E31: VB Akademiet | F31: st@vejle-boldklub.dk | G31: +45 24 97 70 10 | H31: https://vejle-boldklub.dk/vb-akademiet/staben | I31: 2 | J31: Zweryfikowany | K31: 1. Division
A32: Dania | B32: Esbjerg fB | C32: Anders Brynaa | D32: Talentchef | E32: EfB Akademi | F32: ukryty na stronie (ochrona antyspamowa) – skopiuj ze strony | H32: https://efb.dk/efb-akademi/stab/ | I32: 2 | J32: Częściowo – brak maila osoby | K32: 1. Division
A33: Dania | B33: HB Køge | C33: Steen Knudsen | D33: Talentchef | E33: Akademia | F33: sk@hbkoge.dk | G33: +45 40 42 45 59 | H33: https://www.hbkoge.dk/talentudvikling/ | I33: 2 | J33: Zweryfikowany | K33: 1. Division. Klub stawia na wychowanków
A34: Dania | B34: Hvidovre IF | C34: Christian Grønbæk | D34: Talentchef | E34: Talentakademi | F34: cg@hif.dk | G34: hif@hif.dk; 36 78 17 72 | H34: https://bredde.hif.dk/talentakademi/ | I34: 2 | J34: Zweryfikowany | K34: 1. Division
A35: Dania | B35: FC Nordsjælland | C35: Henrik Surel | D35: Emerging Talent Scout U14–U19, Girls | E35: Scouting dziewcząt U14–U19 | F35: ukryty na stronie (ochrona antyspamowa) – skopiuj ze strony | H35: https://fcn.dk/akademi/kontakt | I35: 3 | J35: Częściowo – brak maila osoby | K35: Superliga
A36: Dania | B36: F.C. København | C36: Cornelius Scheel Hjeds | D36: Head Scout U6–U9 | E36: Scouting U6–U9 | F36: cohj@fck.dk | H36: https://www.fck.dk/indhold/procedurer-rekruttering-i-talentafdelingen | I36: 3 | J36: Zweryfikowany | K36: Superliga
A37: Dania | B37: F.C. København | C37: Casper Kåre Hansen | D37: Talent Head, Girls/Women | E37: Akademia kobiet | F37: cakh@fck.dk | H37: https://www.fck.dk/indhold/procedurer-rekruttering-i-talentafdelingen | I37: 3 | J37: Zweryfikowany | K37: Superliga
A38: Dania | B38: Akademisk Boldklub | C38: Simon Andresen | D38: Rekrutacja U17/U19 | E38: Rekrutacja i testy U17–U19 | F38: ukryty na stronie (ochrona antyspamowa) – skopiuj ze strony | G38: formularz „Spillerhenvendelse” na stronie | H38: https://www.akademiskboldklub.dk/klub/akademisk-boldklub--4/sider/spillerhenvendelser | I38: 3 | J38: Częściowo – brak maila osoby | K38: 1. Division
A39: Dania | B39: Kolding IF | C39: Jonas Illum | D39: Talentchef (akademia chłopców i dziewcząt) | E39: Akademia | H39: https://kolding-if.dk/sport/akademiet/kontakt-akademi/ | I39: 3 | J39: Częściowo – brak maila osoby | K39: 1. Division. Starszy kontakt jj@kolding-if.dk (Jacob Jensen, 2024) – nieaktualny
A40: Dania | B40: Hillerød Fodbold | C40: Peter Sørensen | D40: Talentchef | E40: Akademia | G40: info@hilleroedfodbold.dk | H40: https://www.hilleroedfodbold.dk/klubnyt/hilleroed-fodbold-ansaetter-peter-soerensen-som-ny-talentchef/ | I40: 3 | J40: Częściowo – brak maila osoby | K40: 1. Division. Od 01.01.2026
...

Sheet Beşiktaş – korekta
A1: Klub | B1: Osoba | C1: Stanowisko | D1: Obszar działania | E1: E-mail osoby | F1: Źródło | G1: Status weryfikacji | H1: Uwagi
A2: Beşiktaş JK | B2: Serdar Topraktepe | C2: Akademi Direktörü (Academy Director) | D2: Kierowanie akademią | F2: https://bjk.com.tr/tr/spor-okullari/idari_ve_teknik_kadro | G2: Częściowo – brak maila osoby | H2: Stanowisko wg oficjalnej listy kadry
A3: Beşiktaş JK | B3: Toygun Batallı | C3: Altyapı Gelişimden Sorumlu Yönetici | D3: Rozwój młodzieży | F3: https://bjk.com.tr/tr/spor-okullari/idari_ve_teknik_kadro | G3: Częściowo – brak maila osoby
A4: Beşiktaş JK | B4: Onur Kerpikçi | C4: Akademi Scout / Spor Okulları Denetim Müdürü | D4: Scouting akademii, szkółki | F4: https://bjk.com.tr/tr/spor-okullari/idari_ve_teknik_kadro | G4: Częściowo – brak maila osoby
A5: Beşiktaş JK | B5: — | C5: Beşiktaş Futbol Akademi – kontakt ogólny | D5: Adres: Vişnezade Mah. Kadırgalar Cad. No:1, Tüpraş Stadyumu, 34357 Beşiktaş/İstanbul | F5: https://bjk.com.tr/tr/cms/iletisim/14/ | G5: Częściowo – brak maila osoby | H5: Zespół akademii wymieniony na stronie kontaktowej klubu

Sheet Ranking CIES
A1: Ranking CIES | B1: Miejsce | C1: Klub | D1: Kraj | E1: Wynik | F1: Status w bazie
A2: Wychowankowie w ligach Big-5 (WP529, 2026) | B2: 1 | C2: FC Barcelona | D2: Hiszpania | E2: 40 zawodników | F2: Poza zasięgiem – tylko informacyjnie
A3: Wychowankowie w ligach Big-5 (WP529, 2026) | B3: 2 | C3: Real Madrid | D3: Hiszpania | E3: 35 zawodników | F3: Poza zasięgiem – tylko informacyjnie
A4: Wychowankowie w ligach Big-5 (WP529, 2026) | B4: 3 | C4: Paris Saint-Germain | D4: Francja | E4: 31 zawodników | F4: Poza zasięgiem – tylko informacyjnie
A5: Wychowankowie w ligach Big-5 (WP529, 2026) | B5: 4 | C5: Stade Rennais | D5: Francja | E5: 29 zawodników | F5: W arkuszu Kontakty
A6: Wychowankowie w ligach Big-5 (WP529, 2026) | B6: 5 | C6: AFC Ajax | D6: Holandia | E6: 27 zawodników (1. spoza Big-5) | F6: W arkuszu Kontakty
A7: Wychowankowie w ligach Big-5 (WP529, 2026) | B7: 6–10 | C7: Chelsea, Real Sociedad, Man. United, Man. City, Arsenal | D7: Anglia/Hiszpania | E7: — | F7: Real Sociedad w arkuszu Kontakty
A8: Wychowankowie w 31 ligach UEFA (2026) | B8: 1 | C8: AFC Ajax | D8: Holandia | E8: 85 zawodników | F8: W arkuszu Kontakty
A9: Wychowankowie w 31 ligach UEFA (2026) | B9: 2 | C9: SL Benfica | D9: Portugalia | E9: 73 zawodników | F9: W arkuszu Kontakty
A10: Wychowankowie w 31 ligach UEFA (2026) | B10: 3 | C10: Dynamo Kijów | D10: Ukraina | E10: 72 zawodników | F10: W arkuszu Kontakty
A11: Training Index (ważony poziomem) | B11: 3 | C11: Sporting CP | D11: Portugalia | E11: 3. miejsce w obu tabelach | F11: W arkuszu Kontakty
A12: Przychody ze sprzedaży wychowanków – 10 lat (WP540, 2026) | B12: 1 | C12: SL Benfica | D12: Portugalia | E12: 589 mln € | F12: W arkuszu Kontakty
A13: Przychody ze sprzedaży wychowanków – 10 lat (WP540, 2026) | B13: 2 | C13: AFC Ajax | D13: Holandia | E13: 454 mln € | F13: W arkuszu Kontakty
A14: Przychody ze sprzedaży wychowanków – 10 lat (WP540, 2026) | B14: 3 | C14: Chelsea FC | D14: Anglia | E14: 442 mln € | F14: Poza zasięgiem – tylko informacyjnie
A15: Przychody ze sprzedaży wychowanków – 10 lat (WP540, 2026) | B15: 4–10 | C15: Olympique Lyonnais, AS Monaco, Sporting CP, Man. City, Real Madrid, Palmeiras, Bayer Leverkusen | D15: różne | E15: — | F15: Lyon, Monaco, Sporting, Leverkusen w arkuszu Kontakty
A16: Przychody ze sprzedaży wychowanków – 5 lat (WP540, 2026) | B16: 1 | C16: Chelsea FC | D16: Anglia | E16: 366 mln € | F16: Poza zasięgiem – tylko informacyjnie
A17: Przychody ze sprzedaży wychowanków – 5 lat (WP540, 2026) | B17: 2 | C17: Manchester City | D17: Anglia | E17: 318 mln € | F17: Poza zasięgiem – tylko informacyjnie
A18: MR99 (II 2025): wychowankowie w Big-5, 20 lat | B18: 1 | C18: Real Madrid | D18: Hiszpania | E18: 166 zawodników | F18: W arkuszu Kontakty
A19: MR99 (II 2025): wychowankowie w Big-5, 20 lat | B19: 2 | C19: FC Barcelona | D19: Hiszpania | E19: 156 | F19: W arkuszu Kontakty
A20: MR99 (II 2025): wychowankowie w Big-5, 20 lat | B20: 3 | C20: Paris Saint-Germain | D20: Francja | E20: 111 | F20: W arkuszu Kontakty
A21: MR99 (II 2025): wychowankowie w Big-5, 20 lat | B21: 4–5 | C21: Olympique Lyonnais, Manchester United | D21: Francja/Anglia | E21: po 103 | F21: W arkuszu Kontakty
A22: MR99 (II 2025): wychowankowie w Big-5, 20 lat | B22: 6–7 | C22: Stade Rennais, Atalanta | D22: Francja/Włochy | E22: po 94 | F22: W arkuszu Kontakty
A23: MR99 (II 2025): minuty wychowanków w Big-5, 20 lat | B23: top 10 | C23: Real Madrid (1), Barcelona (2), Lyon, PSG, Rennes, Man. United, Athletic Club (7), Atalanta, Real Sociedad (9), Valencia (10) | D23: różne | E23: — | F23: Wszystkie w arkuszu Kontakty
A24: Wychowankowie w 55 ligach (VI 2025) | B24: 1–3 | C24: Real Madrid 103, Benfica 102, Barcelona 94 | D24: różne | E24: — | F24: W arkuszu Kontakty
A25: Wychowankowie w 55 ligach (VI 2025) | B25: 4–10 | C25: Ajax, Sporting CP, River Plate, Defensor, Crvena zvezda, Dinamo Zagreb, Boca Juniors | D25: różne | E25: — | F25: Europejskie kluby w arkuszu Kontakty
A27: Źródła: CIES Football Observatory – Weekly Post 529 (training clubs), Weekly Post 540 (most profitable academies), 2026; Monthly Report 99 (II 2025). football-observatory.com
